<?xml version="1.0" encoding="utf-8"?>
<!-- This URDF was automatically created by SolidWorks to URDF Exporter! Originally created by Stephen Brawner (brawner@gmail.com) 
     Commit Version: 1.6.0-4-g7f85cfe  Build Version: 1.6.7995.38578
     For more information, please see http://wiki.ros.org/sw_urdf_exporter -->
<robot
  name="tracer2">
  <link
    name="base_link">
    <inertial>
      <origin
        xyz="-0.00032354 4.0933E-17 0.092792"
        rpy="0 0 0" />
      <mass
        value="42.875" />
      <inertia
        ixx="1.1428"
        ixy="1.8678E-16"
        ixz="0.0007936"
        iyy="1.508"
        iyz="-3.005E-17"
        izz="2.5405" />
    </inertial>
    <visual>
      <origin
        xyz="0 0 0"
        rpy="0 0 0" />
      <geometry>
        <mesh
          filename="package://tracer2/meshes/base_link.STL" />
      </geometry>
      <material
        name="">
        <color
          rgba="1 1 1 1" />
      </material>
    </visual>
    <collision>
      <origin
        xyz="0 0 0"
        rpy="0 0 0" />
      <geometry>
        <mesh
          filename="package://tracer2/meshes/base_link.STL" />
      </geometry>
    </collision>
  </link>
  <link
    name="rueda_izquierda_Link">
    <inertial>
      <origin
        xyz="-8.4752E-19 0 0.0375"
        rpy="0 0 0" />
      <mass
        value="0.85779" />
      <inertia
        ixx="0.0011549"
        ixy="3.2627E-51"
        ixz="2.9387E-36"
        iyy="0.0011549"
        iyz="-1.3108E-36"
        izz="0.0015842" />
    </inertial>
    <visual>
      <origin
        xyz="0 0 0"
        rpy="0 0 0" />
      <geometry>
        <mesh
          filename="package://tracer2/meshes/rueda_izquierda_Link.STL" />
      </geometry>
      <material
        name="">
        <color
          rgba="0.79216 0.81961 0.93333 1" />
      </material>
    </visual>
    <collision>
      <origin
        xyz="0 0 0"
        rpy="0 0 0" />
      <geometry>
        <mesh
          filename="package://tracer2/meshes/rueda_izquierda_Link.STL" />
      </geometry>
    </collision>
  </link>
  <joint
    name="rueda_izquierda_joint"
    type="continuous">
    <origin
      xyz="0 0.13 0.0625"
      rpy="-1.5708 0 0" />
    <parent
      link="base_link" />
    <child
      link="rueda_izquierda_Link" />
    <axis
      xyz="0 0 1" />
  </joint>
  <link
    name="rueda_derecha_Link">
    <inertial>
      <origin
        xyz="-8.4752E-19 0 -0.0375"
        rpy="0 0 0" />
      <mass
        value="0.85779" />
      <inertia
        ixx="0.0011549"
        ixy="3.2627E-51"
        ixz="2.9387E-36"
        iyy="0.0011549"
        iyz="-1.3108E-36"
        izz="0.0015842" />
    </inertial>
    <visual>
      <origin
        xyz="0 0 0"
        rpy="0 0 0" />
      <geometry>
        <mesh
          filename="package://tracer2/meshes/rueda_derecha_Link.STL" />
      </geometry>
      <material
        name="">
        <color
          rgba="0.79216 0.81961 0.93333 1" />
      </material>
    </visual>
    <collision>
      <origin
        xyz="0 0 0"
        rpy="0 0 0" />
      <geometry>
        <mesh
          filename="package://tracer2/meshes/rueda_derecha_Link.STL" />
      </geometry>
    </collision>
  </link>
  <joint
    name="rueda_derecha_joint"
    type="continuous">
    <origin
      xyz="0 -0.13 0.0625"
      rpy="-1.5708 0 0" />
    <parent
      link="base_link" />
    <child
      link="rueda_derecha_Link" />
    <axis
      xyz="0 0 1" />
  </joint>
  <link
    name="apoyo_izquierdo_delantero_Link">
    <inertial>
      <origin
        xyz="0 -3.4694E-18 -0.025"
        rpy="0 0 0" />
      <mass
        value="0.08509" />
      <inertia
        ixx="2.4033E-05"
        ixy="1.1215E-52"
        ixz="-6.7113E-38"
        iyy="2.4033E-05"
        iyz="-4.3749E-39"
        izz="3.0772E-05" />
    </inertial>
    <visual>
      <origin
        xyz="0 0 0"
        rpy="0 0 0" />
      <geometry>
        <mesh
          filename="package://tracer2/meshes/apoyo_izquierdo_delantero_Link.STL" />
      </geometry>
      <material
        name="">
        <color
          rgba="0.79216 0.81961 0.93333 1" />
      </material>
    </visual>
    <collision>
      <origin
        xyz="0 0 0"
        rpy="0 0 0" />
      <geometry>
        <mesh
          filename="package://tracer2/meshes/apoyo_izquierdo_delantero_Link.STL" />
      </geometry>
    </collision>
  </link>
  <joint
    name="apoyo_izquierdo_delantero_joint"
    type="continuous">
    <origin
      xyz="0.21 0.1425 0.03"
      rpy="1.5708 0 0" />
    <parent
      link="base_link" />
    <child
      link="apoyo_izquierdo_delantero_Link" />
    <axis
      xyz="0 0 1" />
  </joint>
  <link
    name="apoyo_izquierdo_trasero_Link">
    <inertial>
      <origin
        xyz="0 0 -0.025"
        rpy="0 0 0" />
      <mass
        value="0.0850899388486764" />
      <inertia
        ixx="2.40333771513674E-05"
        ixy="0"
        ixz="4.24117892800525E-23"
        iyy="2.40333771513674E-05"
        iyz="1.56849225517708E-23"
        izz="3.0772089396878E-05" />
    </inertial>
    <visual>
      <origin
        xyz="0 0 0"
        rpy="0 0 0" />
      <geometry>
        <mesh
          filename="package://tracer2/meshes/apoyo_izquierdo_trasero_Link.STL" />
      </geometry>
      <material
        name="">
        <color
          rgba="0.792156862745098 0.819607843137255 0.933333333333333 1" />
      </material>
    </visual>
    <collision>
      <origin
        xyz="0 0 0"
        rpy="0 0 0" />
      <geometry>
        <mesh
          filename="package://tracer2/meshes/apoyo_izquierdo_trasero_Link.STL" />
      </geometry>
    </collision>
  </link>
  <joint
    name="apoyo_izquierdo_trasero_joint"
    type="continuous">
    <origin
      xyz="-0.21 0.1425 0.03"
      rpy="1.5708 1.2815 0" />
    <parent
      link="base_link" />
    <child
      link="apoyo_izquierdo_trasero_Link" />
    <axis
      xyz="0 0 1" />
  </joint>
  <link
    name="apoyo_derecho_delantero_Link">
    <inertial>
      <origin
        xyz="2.77555756156289E-17 -3.46944695195361E-18 0.025"
        rpy="0 0 0" />
      <mass
        value="0.0850899388486764" />
      <inertia
        ixx="2.40333771513674E-05"
        ixy="1.12153670543725E-52"
        ixz="-6.71126128087714E-38"
        iyy="2.40333771513674E-05"
        iyz="-4.37492629618135E-39"
        izz="3.0772089396878E-05" />
    </inertial>
    <visual>
      <origin
        xyz="0 0 0"
        rpy="0 0 0" />
      <geometry>
        <mesh
          filename="package://tracer2/meshes/apoyo_derecho_delantero_Link.STL" />
      </geometry>
      <material
        name="">
        <color
          rgba="0.792156862745098 0.819607843137255 0.933333333333333 1" />
      </material>
    </visual>
    <collision>
      <origin
        xyz="0 0 0"
        rpy="0 0 0" />
      <geometry>
        <mesh
          filename="package://tracer2/meshes/apoyo_derecho_delantero_Link.STL" />
      </geometry>
    </collision>
  </link>
  <joint
    name="apoyo_derecho_delantero_joint"
    type="continuous">
    <origin
      xyz="0.21 -0.1425 0.03"
      rpy="1.5708 0 0" />
    <parent
      link="base_link" />
    <child
      link="apoyo_derecho_delantero_Link" />
    <axis
      xyz="0 0 1" />
  </joint>
  <link
    name="apoyo_derecho_trasero_Link">
    <inertial>
      <origin
        xyz="0 -6.9389E-18 0.025"
        rpy="0 0 0" />
      <mass
        value="0.08509" />
      <inertia
        ixx="2.4033E-05"
        ixy="0"
        ixz="-1.0848E-22"
        iyy="2.4033E-05"
        iyz="3.2936E-24"
        izz="3.0772E-05" />
    </inertial>
    <visual>
      <origin
        xyz="0 0 0"
        rpy="0 0 0" />
      <geometry>
        <mesh
          filename="package://tracer2/meshes/apoyo_derecho_trasero_Link.STL" />
      </geometry>
      <material
        name="">
        <color
          rgba="0.79216 0.81961 0.93333 1" />
      </material>
    </visual>
    <collision>
      <origin
        xyz="0 0 0"
        rpy="0 0 0" />
      <geometry>
        <mesh
          filename="package://tracer2/meshes/apoyo_derecho_trasero_Link.STL" />
      </geometry>
    </collision>
  </link>
  <joint
    name="apoyo_derecho_trasero_joint"
    type="continuous">
    <origin
      xyz="-0.21 -0.1425 0.03"
      rpy="1.5708 -0.040768 0" />
    <parent
      link="base_link" />
    <child
      link="apoyo_derecho_trasero_Link" />
    <axis
      xyz="0 0 1" />
  </joint>
  
  
  
   <link name="rslidar_link">
    <visual>
      <origin xyz="0.0 0.0 0.0" />
      <geometry>
        <cylinder length="0.07" radius="0.03" />
      </geometry>
      <material name="orange" />
    </visual>
  </link>

  <joint name="rslidar_joint" type="fixed">
    <parent link="base_link" />
    <child link="rslidar_link" />
    <origin xyz="0.2125 0 0.20" rpy="0 0 0" />
  </joint>
  

  <link name="imu_link">
    <visual>
      <geometry>
        <box size="0.1 0.1 0.05"/>
      </geometry>
    </visual>
    <collision>
      <geometry>
        <box size="0.2 0.2 0.05"/>
      </geometry>
    </collision>
    <inertial>
      <mass value="1e-5" />
      <origin xyz="0 0 0" rpy="0 0 0"/>
      <inertia ixx="1e-6" ixy="0" ixz="0" iyy="1e-6" iyz="0" izz="1e-6" />
    </inertial>
  </link>

  
 <joint name="imu_joint" type="fixed">
    <origin xyz="0 0 0.15" rpy="0 0 0" />
    <parent link="base_link" />
    <child link="imu_link" />
</joint> 
 
  
   <joint name="camera_joint" type="fixed">
    <parent link="base_link"/>
    <child link="camera_link"/>
    <origin xyz="0.305 0 0.2" rpy="0 0 0"/>
</joint>

<link name="camera_link">
    <visual>
        <geometry>
            <box size="0.010 0.03 0.03"/>
        </geometry>
        <material name="red"/>
    </visual>
</link>

<link name="camera_link_optical"></link>

<joint name="camera_optical_joint" type="fixed">
    <origin xyz="0 0 0" rpy="-1.570796 0 -1.570796" />
    <parent link="camera_link" />
    <child link="camera_link_optical" />
</joint>
  
  
   <gazebo>
    <plugin name="differential_drive_controller" filename="libgazebo_ros_diff_drive.so">
      <alwaysOn>false</alwaysOn>
      <legacyMode>false</legacyMode>
      <updateRate>50</updateRate>
      <leftJoint>rueda_izquierda_joint</leftJoint>
      <rightJoint>rueda_derecha_joint</rightJoint>
      <wheelSeparation>0.335</wheelSeparation>
      <wheelDiameter>0.125</wheelDiameter>
      <torque>20</torque>
      <commandTopic>cmd_vel</commandTopic>
      <odometryTopic>odom</odometryTopic>
      <odometryFrame>odom</odometryFrame>
      <robotBaseFrame>base_link</robotBaseFrame>
    </plugin>
  </gazebo>
  
   <gazebo reference="rslidar_link">
    <sensor type="ray" name="head_hokuyo_sensor">
      <pose>0 0 0 0 0 0</pose>
      <visualize>true</visualize>
      <update_rate>40</update_rate>
      <ray>
        <scan>
          <horizontal>
            <samples>720</samples>
            <resolution>1</resolution>
            <min_angle>-1.570796</min_angle>
            <max_angle>1.570796</max_angle>
          </horizontal>
        </scan>
        <range>
          <min>0.10</min>
          <max>30.0</max>
          <resolution>0.01</resolution>
        </range>
        <noise>
          <type>gaussian</type>
          <!-- Noise parameters based on published spec for Hokuyo laser
               achieving "+-30mm" accuracy at range < 10m.  A mean of 0.0m and
               stddev of 0.01m will put 99.7% of samples within 0.03m of the true
               reading. -->
          <mean>0.0</mean>
          <stddev>0.01</stddev>
        </noise>
      </ray>
      <plugin name="gazebo_ros_head_hokuyo_controller" filename="libgazebo_ros_laser.so">
        <topicName>/scan</topicName>
        <frameName>rslidar_link</frameName>
      </plugin>
    </sensor>
  </gazebo>
  
   <gazebo reference="camera_link">
        <material>Gazebo/Red</material>
 
        <sensor name="camera" type="camera">
            <pose> 0 0 0 0 0 0 </pose>
            <visualize>true</visualize>
            <update_rate>10</update_rate>
            <camera>
                <horizontal_fov>1.089</horizontal_fov>
                <image>
                    <format>R8G8B8</format>
                    <width>640</width>
                    <height>480</height>
                </image>
                <clip>
                    <near>0.05</near>
                    <far>8.0</far>
                </clip>
            </camera>
            <plugin name="camera_controller" filename="libgazebo_ros_camera.so">
                <frame_name>camera_link_optical</frame_name>
            </plugin>
        </sensor>
    </gazebo>
    
   
    <gazebo reference="imu_link">
    <gravity>true</gravity>
    <sensor name="imu_sensor" type="imu">
      <always_on>true</always_on>
      <update_rate>100</update_rate>
      <visualize>true</visualize>
      <topic>__default_topic__</topic>
      <plugin filename="libgazebo_ros_imu_sensor.so" name="imu_plugin">
        <topicName>imu</topicName>
        <bodyName>imu_link</bodyName>
        <updateRateHZ>10.0</updateRateHZ>
        <gaussianNoise>0.0</gaussianNoise>
        <xyzOffset>0 0 0</xyzOffset>
        <rpyOffset>0 0 0</rpyOffset>
        <frameName>imu_link</frameName>
      </plugin>
      <pose>0 0 0 0 0 0</pose>
    </sensor>
  </gazebo>
  
</robot>
